import { describe, it, expect, vi } from 'vitest';
import { render, screen } from '@/test/utils';
import userEvent from '@testing-library/user-event';
import { ErrorBoundary } from '../ErrorBoundary';

// Component that throws an error
const ThrowError = ({ shouldThrow }: { shouldThrow: boolean }) => {
  if (shouldThrow) {
    throw new Error('Test error message');
  }
  return <div>Normal content</div>;
};

describe('ErrorBoundary', () => {
  // Mock console.error to avoid noise in test output
  const consoleSpy = vi.spyOn(console, 'error').mockImplementation(() => {});

  it('renders children when there is no error', () => {
    render(
      <ErrorBoundary>
        <ThrowError shouldThrow={false} />
      </ErrorBoundary>
    );

    expect(screen.getByText('Normal content')).toBeInTheDocument();
  });

  it('renders error message when there is an error', () => {
    render(
      <ErrorBoundary>
        <ThrowError shouldThrow={true} />
      </ErrorBoundary>
    );

    expect(screen.getByText('Something went wrong')).toBeInTheDocument();
    expect(screen.getByText('Test error message')).toBeInTheDocument();
  });

  it('renders custom fallback when provided', () => {
    const customFallback = <div>Custom error fallback</div>;
    
    render(
      <ErrorBoundary fallback={customFallback}>
        <ThrowError shouldThrow={true} />
      </ErrorBoundary>
    );

    expect(screen.getByText('Custom error fallback')).toBeInTheDocument();
    expect(screen.queryByText('Something went wrong')).not.toBeInTheDocument();
  });

  it('shows try again button when error occurs', async () => {
    render(
      <ErrorBoundary>
        <ThrowError shouldThrow={true} />
      </ErrorBoundary>
    );

    // Error should be displayed
    expect(screen.getByText('Something went wrong')).toBeInTheDocument();
    expect(screen.getByText('Try again')).toBeInTheDocument();
  });

  it('displays generic error message when error has no message', () => {
    const ThrowErrorWithoutMessage = () => {
      throw new Error();
    };

    render(
      <ErrorBoundary>
        <ThrowErrorWithoutMessage />
      </ErrorBoundary>
    );

    expect(screen.getByText('An unexpected error occurred')).toBeInTheDocument();
  });

  it('logs error to console', () => {
    // Clear previous calls
    consoleSpy.mockClear();
    
    render(
      <ErrorBoundary>
        <ThrowError shouldThrow={true} />
      </ErrorBoundary>
    );

    expect(consoleSpy).toHaveBeenCalled();
  });

  // Cleanup
  consoleSpy.mockRestore();
});
